<mujoco model="dg5f_left">
  <compiler angle="radian"/>

  <asset>
    <mesh name="ll_dg_mount_c_00" content_type="model/stl" file="meshes/ll_dg_mount_c_00.stl"/>
    <mesh name="ll_dg_mount_c_01" content_type="model/stl" file="meshes/ll_dg_mount_c_01.stl"/>
    <mesh name="ll_dg_mount_c_02" content_type="model/stl" file="meshes/ll_dg_mount_c_02.stl"/>
    <mesh name="ll_dg_mount_c_03" content_type="model/stl" file="meshes/ll_dg_mount_c_03.stl"/>
    <mesh name="ll_dg_mount_c_04" content_type="model/stl" file="meshes/ll_dg_mount_c_04.stl"/>
    <mesh name="ll_dg_mount_c_05" content_type="model/stl" file="meshes/ll_dg_mount_c_05.stl"/>
    <mesh name="ll_dg_mount_c_06" content_type="model/stl" file="meshes/ll_dg_mount_c_06.stl"/>
    <mesh name="ll_dg_mount_c_07" content_type="model/stl" file="meshes/ll_dg_mount_c_07.stl"/>
    <mesh name="ll_dg_base_c_00" content_type="model/stl" file="meshes/ll_dg_base_c_00.stl"/>
    <mesh name="ll_dg_base_c_01" content_type="model/stl" file="meshes/ll_dg_base_c_01.stl"/>
    <mesh name="ll_dg_base_c_02" content_type="model/stl" file="meshes/ll_dg_base_c_02.stl"/>
    <mesh name="ll_dg_base_c_03" content_type="model/stl" file="meshes/ll_dg_base_c_03.stl"/>
    <mesh name="ll_dg_base_c_04" content_type="model/stl" file="meshes/ll_dg_base_c_04.stl"/>
    <mesh name="ll_dg_base_c_05" content_type="model/stl" file="meshes/ll_dg_base_c_05.stl"/>
    <mesh name="ll_dg_base_c_06" content_type="model/stl" file="meshes/ll_dg_base_c_06.stl"/>
    <mesh name="ll_dg_base_c_07" content_type="model/stl" file="meshes/ll_dg_base_c_07.stl"/>
    <mesh name="ll_dg_palm_c_00" content_type="model/stl" file="meshes/ll_dg_palm_c_00.stl"/>
    <mesh name="ll_dg_palm_c_01" content_type="model/stl" file="meshes/ll_dg_palm_c_01.stl"/>
    <mesh name="ll_dg_palm_c_02" content_type="model/stl" file="meshes/ll_dg_palm_c_02.stl"/>
    <mesh name="ll_dg_palm_c_03" content_type="model/stl" file="meshes/ll_dg_palm_c_03.stl"/>
    <mesh name="ll_dg_palm_c_04" content_type="model/stl" file="meshes/ll_dg_palm_c_04.stl"/>
    <mesh name="ll_dg_palm_c_05" content_type="model/stl" file="meshes/ll_dg_palm_c_05.stl"/>
    <mesh name="ll_dg_palm_c_06" content_type="model/stl" file="meshes/ll_dg_palm_c_06.stl"/>
    <mesh name="ll_dg_palm_c_07" content_type="model/stl" file="meshes/ll_dg_palm_c_07.stl"/>
    <mesh name="ll_dg_1_1_c_00" content_type="model/stl" file="meshes/ll_dg_1_1_c_00.stl"/>
    <mesh name="ll_dg_1_1_c_01" content_type="model/stl" file="meshes/ll_dg_1_1_c_01.stl"/>
    <mesh name="ll_dg_1_1_c_02" content_type="model/stl" file="meshes/ll_dg_1_1_c_02.stl"/>
    <mesh name="ll_dg_1_1_c_03" content_type="model/stl" file="meshes/ll_dg_1_1_c_03.stl"/>
    <mesh name="ll_dg_1_1_c_04" content_type="model/stl" file="meshes/ll_dg_1_1_c_04.stl"/>
    <mesh name="ll_dg_1_1_c_05" content_type="model/stl" file="meshes/ll_dg_1_1_c_05.stl"/>
    <mesh name="ll_dg_1_1_c_06" content_type="model/stl" file="meshes/ll_dg_1_1_c_06.stl"/>
    <mesh name="ll_dg_1_1_c_07" content_type="model/stl" file="meshes/ll_dg_1_1_c_07.stl"/>
    <mesh name="ll_dg_1_2_c_00" content_type="model/stl" file="meshes/ll_dg_1_2_c_00.stl"/>
    <mesh name="ll_dg_1_2_c_01" content_type="model/stl" file="meshes/ll_dg_1_2_c_01.stl"/>
    <mesh name="ll_dg_1_2_c_02" content_type="model/stl" file="meshes/ll_dg_1_2_c_02.stl"/>
    <mesh name="ll_dg_1_2_c_03" content_type="model/stl" file="meshes/ll_dg_1_2_c_03.stl"/>
    <mesh name="ll_dg_1_2_c_04" content_type="model/stl" file="meshes/ll_dg_1_2_c_04.stl"/>
    <mesh name="ll_dg_1_2_c_05" content_type="model/stl" file="meshes/ll_dg_1_2_c_05.stl"/>
    <mesh name="ll_dg_1_2_c_06" content_type="model/stl" file="meshes/ll_dg_1_2_c_06.stl"/>
    <mesh name="ll_dg_1_2_c_07" content_type="model/stl" file="meshes/ll_dg_1_2_c_07.stl"/>
    <mesh name="ll_dg_1_3_c_00" content_type="model/stl" file="meshes/ll_dg_1_3_c_00.stl"/>
    <mesh name="ll_dg_1_3_c_01" content_type="model/stl" file="meshes/ll_dg_1_3_c_01.stl"/>
    <mesh name="ll_dg_1_3_c_02" content_type="model/stl" file="meshes/ll_dg_1_3_c_02.stl"/>
    <mesh name="ll_dg_1_3_c_03" content_type="model/stl" file="meshes/ll_dg_1_3_c_03.stl"/>
    <mesh name="ll_dg_1_3_c_04" content_type="model/stl" file="meshes/ll_dg_1_3_c_04.stl"/>
    <mesh name="ll_dg_1_3_c_05" content_type="model/stl" file="meshes/ll_dg_1_3_c_05.stl"/>
    <mesh name="ll_dg_1_3_c_06" content_type="model/stl" file="meshes/ll_dg_1_3_c_06.stl"/>
    <mesh name="ll_dg_1_3_c_07" content_type="model/stl" file="meshes/ll_dg_1_3_c_07.stl"/>
    <mesh name="ll_dg_1_4_c_00" content_type="model/stl" file="meshes/ll_dg_1_4_c_00.stl"/>
    <mesh name="ll_dg_1_4_c_01" content_type="model/stl" file="meshes/ll_dg_1_4_c_01.stl"/>
    <mesh name="ll_dg_1_4_c_02" content_type="model/stl" file="meshes/ll_dg_1_4_c_02.stl"/>
    <mesh name="ll_dg_1_4_c_03" content_type="model/stl" file="meshes/ll_dg_1_4_c_03.stl"/>
    <mesh name="ll_dg_1_4_c_04" content_type="model/stl" file="meshes/ll_dg_1_4_c_04.stl"/>
    <mesh name="ll_dg_1_4_c_05" content_type="model/stl" file="meshes/ll_dg_1_4_c_05.stl"/>
    <mesh name="ll_dg_1_4_c_06" content_type="model/stl" file="meshes/ll_dg_1_4_c_06.stl"/>
    <mesh name="ll_dg_1_4_c_07" content_type="model/stl" file="meshes/ll_dg_1_4_c_07.stl"/>
    <mesh name="ll_dg_1_tip_c_00" content_type="model/stl" file="meshes/ll_dg_1_tip_c_00.stl"/>
    <mesh name="ll_dg_1_tip_c_01" content_type="model/stl" file="meshes/ll_dg_1_tip_c_01.stl"/>
    <mesh name="ll_dg_1_tip_c_02" content_type="model/stl" file="meshes/ll_dg_1_tip_c_02.stl"/>
    <mesh name="ll_dg_1_tip_c_03" content_type="model/stl" file="meshes/ll_dg_1_tip_c_03.stl"/>
    <mesh name="ll_dg_1_tip_c_04" content_type="model/stl" file="meshes/ll_dg_1_tip_c_04.stl"/>
    <mesh name="ll_dg_1_tip_c_05" content_type="model/stl" file="meshes/ll_dg_1_tip_c_05.stl"/>
    <mesh name="ll_dg_1_tip_c_06" content_type="model/stl" file="meshes/ll_dg_1_tip_c_06.stl"/>
    <mesh name="ll_dg_1_tip_c_07" content_type="model/stl" file="meshes/ll_dg_1_tip_c_07.stl"/>
    <mesh name="ll_dg_2_1_c_00" content_type="model/stl" file="meshes/ll_dg_2_1_c_00.stl"/>
    <mesh name="ll_dg_2_1_c_01" content_type="model/stl" file="meshes/ll_dg_2_1_c_01.stl"/>
    <mesh name="ll_dg_2_1_c_02" content_type="model/stl" file="meshes/ll_dg_2_1_c_02.stl"/>
    <mesh name="ll_dg_2_1_c_03" content_type="model/stl" file="meshes/ll_dg_2_1_c_03.stl"/>
    <mesh name="ll_dg_2_1_c_04" content_type="model/stl" file="meshes/ll_dg_2_1_c_04.stl"/>
    <mesh name="ll_dg_2_1_c_05" content_type="model/stl" file="meshes/ll_dg_2_1_c_05.stl"/>
    <mesh name="ll_dg_2_1_c_06" content_type="model/stl" file="meshes/ll_dg_2_1_c_06.stl"/>
    <mesh name="ll_dg_2_1_c_07" content_type="model/stl" file="meshes/ll_dg_2_1_c_07.stl"/>
    <mesh name="ll_dg_2_2_c_00" content_type="model/stl" file="meshes/ll_dg_2_2_c_00.stl"/>
    <mesh name="ll_dg_2_2_c_01" content_type="model/stl" file="meshes/ll_dg_2_2_c_01.stl"/>
    <mesh name="ll_dg_2_2_c_02" content_type="model/stl" file="meshes/ll_dg_2_2_c_02.stl"/>
    <mesh name="ll_dg_2_2_c_03" content_type="model/stl" file="meshes/ll_dg_2_2_c_03.stl"/>
    <mesh name="ll_dg_2_2_c_04" content_type="model/stl" file="meshes/ll_dg_2_2_c_04.stl"/>
    <mesh name="ll_dg_2_2_c_05" content_type="model/stl" file="meshes/ll_dg_2_2_c_05.stl"/>
    <mesh name="ll_dg_2_2_c_06" content_type="model/stl" file="meshes/ll_dg_2_2_c_06.stl"/>
    <mesh name="ll_dg_2_2_c_07" content_type="model/stl" file="meshes/ll_dg_2_2_c_07.stl"/>
    <mesh name="ll_dg_2_3_c_00" content_type="model/stl" file="meshes/ll_dg_2_3_c_00.stl"/>
    <mesh name="ll_dg_2_3_c_01" content_type="model/stl" file="meshes/ll_dg_2_3_c_01.stl"/>
    <mesh name="ll_dg_2_3_c_02" content_type="model/stl" file="meshes/ll_dg_2_3_c_02.stl"/>
    <mesh name="ll_dg_2_3_c_03" content_type="model/stl" file="meshes/ll_dg_2_3_c_03.stl"/>
    <mesh name="ll_dg_2_3_c_04" content_type="model/stl" file="meshes/ll_dg_2_3_c_04.stl"/>
    <mesh name="ll_dg_2_3_c_05" content_type="model/stl" file="meshes/ll_dg_2_3_c_05.stl"/>
    <mesh name="ll_dg_2_3_c_06" content_type="model/stl" file="meshes/ll_dg_2_3_c_06.stl"/>
    <mesh name="ll_dg_2_3_c_07" content_type="model/stl" file="meshes/ll_dg_2_3_c_07.stl"/>
    <mesh name="ll_dg_2_4_c_00" content_type="model/stl" file="meshes/ll_dg_2_4_c_00.stl"/>
    <mesh name="ll_dg_2_4_c_01" content_type="model/stl" file="meshes/ll_dg_2_4_c_01.stl"/>
    <mesh name="ll_dg_2_4_c_02" content_type="model/stl" file="meshes/ll_dg_2_4_c_02.stl"/>
    <mesh name="ll_dg_2_4_c_03" content_type="model/stl" file="meshes/ll_dg_2_4_c_03.stl"/>
    <mesh name="ll_dg_2_4_c_04" content_type="model/stl" file="meshes/ll_dg_2_4_c_04.stl"/>
    <mesh name="ll_dg_2_4_c_05" content_type="model/stl" file="meshes/ll_dg_2_4_c_05.stl"/>
    <mesh name="ll_dg_2_4_c_06" content_type="model/stl" file="meshes/ll_dg_2_4_c_06.stl"/>
    <mesh name="ll_dg_2_4_c_07" content_type="model/stl" file="meshes/ll_dg_2_4_c_07.stl"/>
    <mesh name="ll_dg_2_tip_c_00" content_type="model/stl" file="meshes/ll_dg_2_tip_c_00.stl"/>
    <mesh name="ll_dg_2_tip_c_01" content_type="model/stl" file="meshes/ll_dg_2_tip_c_01.stl"/>
    <mesh name="ll_dg_2_tip_c_02" content_type="model/stl" file="meshes/ll_dg_2_tip_c_02.stl"/>
    <mesh name="ll_dg_2_tip_c_03" content_type="model/stl" file="meshes/ll_dg_2_tip_c_03.stl"/>
    <mesh name="ll_dg_2_tip_c_04" content_type="model/stl" file="meshes/ll_dg_2_tip_c_04.stl"/>
    <mesh name="ll_dg_2_tip_c_05" content_type="model/stl" file="meshes/ll_dg_2_tip_c_05.stl"/>
    <mesh name="ll_dg_2_tip_c_06" content_type="model/stl" file="meshes/ll_dg_2_tip_c_06.stl"/>
    <mesh name="ll_dg_2_tip_c_07" content_type="model/stl" file="meshes/ll_dg_2_tip_c_07.stl"/>
    <mesh name="ll_dg_3_1_c_00" content_type="model/stl" file="meshes/ll_dg_3_1_c_00.stl"/>
    <mesh name="ll_dg_3_1_c_01" content_type="model/stl" file="meshes/ll_dg_3_1_c_01.stl"/>
    <mesh name="ll_dg_3_1_c_02" content_type="model/stl" file="meshes/ll_dg_3_1_c_02.stl"/>
    <mesh name="ll_dg_3_1_c_03" content_type="model/stl" file="meshes/ll_dg_3_1_c_03.stl"/>
    <mesh name="ll_dg_3_1_c_04" content_type="model/stl" file="meshes/ll_dg_3_1_c_04.stl"/>
    <mesh name="ll_dg_3_1_c_05" content_type="model/stl" file="meshes/ll_dg_3_1_c_05.stl"/>
    <mesh name="ll_dg_3_1_c_06" content_type="model/stl" file="meshes/ll_dg_3_1_c_06.stl"/>
    <mesh name="ll_dg_3_1_c_07" content_type="model/stl" file="meshes/ll_dg_3_1_c_07.stl"/>
    <mesh name="ll_dg_3_2_c_00" content_type="model/stl" file="meshes/ll_dg_3_2_c_00.stl"/>
    <mesh name="ll_dg_3_2_c_01" content_type="model/stl" file="meshes/ll_dg_3_2_c_01.stl"/>
    <mesh name="ll_dg_3_2_c_02" content_type="model/stl" file="meshes/ll_dg_3_2_c_02.stl"/>
    <mesh name="ll_dg_3_2_c_03" content_type="model/stl" file="meshes/ll_dg_3_2_c_03.stl"/>
    <mesh name="ll_dg_3_2_c_04" content_type="model/stl" file="meshes/ll_dg_3_2_c_04.stl"/>
    <mesh name="ll_dg_3_2_c_05" content_type="model/stl" file="meshes/ll_dg_3_2_c_05.stl"/>
    <mesh name="ll_dg_3_2_c_06" content_type="model/stl" file="meshes/ll_dg_3_2_c_06.stl"/>
    <mesh name="ll_dg_3_2_c_07" content_type="model/stl" file="meshes/ll_dg_3_2_c_07.stl"/>
    <mesh name="ll_dg_3_3_c_00" content_type="model/stl" file="meshes/ll_dg_3_3_c_00.stl"/>
    <mesh name="ll_dg_3_3_c_01" content_type="model/stl" file="meshes/ll_dg_3_3_c_01.stl"/>
    <mesh name="ll_dg_3_3_c_02" content_type="model/stl" file="meshes/ll_dg_3_3_c_02.stl"/>
    <mesh name="ll_dg_3_3_c_03" content_type="model/stl" file="meshes/ll_dg_3_3_c_03.stl"/>
    <mesh name="ll_dg_3_3_c_04" content_type="model/stl" file="meshes/ll_dg_3_3_c_04.stl"/>
    <mesh name="ll_dg_3_3_c_05" content_type="model/stl" file="meshes/ll_dg_3_3_c_05.stl"/>
    <mesh name="ll_dg_3_3_c_06" content_type="model/stl" file="meshes/ll_dg_3_3_c_06.stl"/>
    <mesh name="ll_dg_3_3_c_07" content_type="model/stl" file="meshes/ll_dg_3_3_c_07.stl"/>
    <mesh name="ll_dg_3_4_c_00" content_type="model/stl" file="meshes/ll_dg_3_4_c_00.stl"/>
    <mesh name="ll_dg_3_4_c_01" content_type="model/stl" file="meshes/ll_dg_3_4_c_01.stl"/>
    <mesh name="ll_dg_3_4_c_02" content_type="model/stl" file="meshes/ll_dg_3_4_c_02.stl"/>
    <mesh name="ll_dg_3_4_c_03" content_type="model/stl" file="meshes/ll_dg_3_4_c_03.stl"/>
    <mesh name="ll_dg_3_4_c_04" content_type="model/stl" file="meshes/ll_dg_3_4_c_04.stl"/>
    <mesh name="ll_dg_3_4_c_05" content_type="model/stl" file="meshes/ll_dg_3_4_c_05.stl"/>
    <mesh name="ll_dg_3_4_c_06" content_type="model/stl" file="meshes/ll_dg_3_4_c_06.stl"/>
    <mesh name="ll_dg_3_4_c_07" content_type="model/stl" file="meshes/ll_dg_3_4_c_07.stl"/>
    <mesh name="ll_dg_3_tip_c_00" content_type="model/stl" file="meshes/ll_dg_3_tip_c_00.stl"/>
    <mesh name="ll_dg_3_tip_c_01" content_type="model/stl" file="meshes/ll_dg_3_tip_c_01.stl"/>
    <mesh name="ll_dg_3_tip_c_02" content_type="model/stl" file="meshes/ll_dg_3_tip_c_02.stl"/>
    <mesh name="ll_dg_3_tip_c_03" content_type="model/stl" file="meshes/ll_dg_3_tip_c_03.stl"/>
    <mesh name="ll_dg_3_tip_c_04" content_type="model/stl" file="meshes/ll_dg_3_tip_c_04.stl"/>
    <mesh name="ll_dg_3_tip_c_05" content_type="model/stl" file="meshes/ll_dg_3_tip_c_05.stl"/>
    <mesh name="ll_dg_3_tip_c_06" content_type="model/stl" file="meshes/ll_dg_3_tip_c_06.stl"/>
    <mesh name="ll_dg_3_tip_c_07" content_type="model/stl" file="meshes/ll_dg_3_tip_c_07.stl"/>
    <mesh name="ll_dg_4_1_c_00" content_type="model/stl" file="meshes/ll_dg_4_1_c_00.stl"/>
    <mesh name="ll_dg_4_1_c_01" content_type="model/stl" file="meshes/ll_dg_4_1_c_01.stl"/>
    <mesh name="ll_dg_4_1_c_02" content_type="model/stl" file="meshes/ll_dg_4_1_c_02.stl"/>
    <mesh name="ll_dg_4_1_c_03" content_type="model/stl" file="meshes/ll_dg_4_1_c_03.stl"/>
    <mesh name="ll_dg_4_1_c_04" content_type="model/stl" file="meshes/ll_dg_4_1_c_04.stl"/>
    <mesh name="ll_dg_4_1_c_05" content_type="model/stl" file="meshes/ll_dg_4_1_c_05.stl"/>
    <mesh name="ll_dg_4_1_c_06" content_type="model/stl" file="meshes/ll_dg_4_1_c_06.stl"/>
    <mesh name="ll_dg_4_1_c_07" content_type="model/stl" file="meshes/ll_dg_4_1_c_07.stl"/>
    <mesh name="ll_dg_4_2_c_00" content_type="model/stl" file="meshes/ll_dg_4_2_c_00.stl"/>
    <mesh name="ll_dg_4_2_c_01" content_type="model/stl" file="meshes/ll_dg_4_2_c_01.stl"/>
    <mesh name="ll_dg_4_2_c_02" content_type="model/stl" file="meshes/ll_dg_4_2_c_02.stl"/>
    <mesh name="ll_dg_4_2_c_03" content_type="model/stl" file="meshes/ll_dg_4_2_c_03.stl"/>
    <mesh name="ll_dg_4_2_c_04" content_type="model/stl" file="meshes/ll_dg_4_2_c_04.stl"/>
    <mesh name="ll_dg_4_2_c_05" content_type="model/stl" file="meshes/ll_dg_4_2_c_05.stl"/>
    <mesh name="ll_dg_4_2_c_06" content_type="model/stl" file="meshes/ll_dg_4_2_c_06.stl"/>
    <mesh name="ll_dg_4_2_c_07" content_type="model/stl" file="meshes/ll_dg_4_2_c_07.stl"/>
    <mesh name="ll_dg_4_3_c_00" content_type="model/stl" file="meshes/ll_dg_4_3_c_00.stl"/>
    <mesh name="ll_dg_4_3_c_01" content_type="model/stl" file="meshes/ll_dg_4_3_c_01.stl"/>
    <mesh name="ll_dg_4_3_c_02" content_type="model/stl" file="meshes/ll_dg_4_3_c_02.stl"/>
    <mesh name="ll_dg_4_3_c_03" content_type="model/stl" file="meshes/ll_dg_4_3_c_03.stl"/>
    <mesh name="ll_dg_4_3_c_04" content_type="model/stl" file="meshes/ll_dg_4_3_c_04.stl"/>
    <mesh name="ll_dg_4_3_c_05" content_type="model/stl" file="meshes/ll_dg_4_3_c_05.stl"/>
    <mesh name="ll_dg_4_3_c_06" content_type="model/stl" file="meshes/ll_dg_4_3_c_06.stl"/>
    <mesh name="ll_dg_4_3_c_07" content_type="model/stl" file="meshes/ll_dg_4_3_c_07.stl"/>
    <mesh name="ll_dg_4_4_c_00" content_type="model/stl" file="meshes/ll_dg_4_4_c_00.stl"/>
    <mesh name="ll_dg_4_4_c_01" content_type="model/stl" file="meshes/ll_dg_4_4_c_01.stl"/>
    <mesh name="ll_dg_4_4_c_02" content_type="model/stl" file="meshes/ll_dg_4_4_c_02.stl"/>
    <mesh name="ll_dg_4_4_c_03" content_type="model/stl" file="meshes/ll_dg_4_4_c_03.stl"/>
    <mesh name="ll_dg_4_4_c_04" content_type="model/stl" file="meshes/ll_dg_4_4_c_04.stl"/>
    <mesh name="ll_dg_4_4_c_05" content_type="model/stl" file="meshes/ll_dg_4_4_c_05.stl"/>
    <mesh name="ll_dg_4_4_c_06" content_type="model/stl" file="meshes/ll_dg_4_4_c_06.stl"/>
    <mesh name="ll_dg_4_4_c_07" content_type="model/stl" file="meshes/ll_dg_4_4_c_07.stl"/>
    <mesh name="ll_dg_4_tip_c_00" content_type="model/stl" file="meshes/ll_dg_4_tip_c_00.stl"/>
    <mesh name="ll_dg_4_tip_c_01" content_type="model/stl" file="meshes/ll_dg_4_tip_c_01.stl"/>
    <mesh name="ll_dg_4_tip_c_02" content_type="model/stl" file="meshes/ll_dg_4_tip_c_02.stl"/>
    <mesh name="ll_dg_4_tip_c_03" content_type="model/stl" file="meshes/ll_dg_4_tip_c_03.stl"/>
    <mesh name="ll_dg_4_tip_c_04" content_type="model/stl" file="meshes/ll_dg_4_tip_c_04.stl"/>
    <mesh name="ll_dg_4_tip_c_05" content_type="model/stl" file="meshes/ll_dg_4_tip_c_05.stl"/>
    <mesh name="ll_dg_4_tip_c_06" content_type="model/stl" file="meshes/ll_dg_4_tip_c_06.stl"/>
    <mesh name="ll_dg_4_tip_c_07" content_type="model/stl" file="meshes/ll_dg_4_tip_c_07.stl"/>
    <mesh name="ll_dg_5_1_c_00" content_type="model/stl" file="meshes/ll_dg_5_1_c_00.stl"/>
    <mesh name="ll_dg_5_1_c_01" content_type="model/stl" file="meshes/ll_dg_5_1_c_01.stl"/>
    <mesh name="ll_dg_5_1_c_02" content_type="model/stl" file="meshes/ll_dg_5_1_c_02.stl"/>
    <mesh name="ll_dg_5_1_c_03" content_type="model/stl" file="meshes/ll_dg_5_1_c_03.stl"/>
    <mesh name="ll_dg_5_1_c_04" content_type="model/stl" file="meshes/ll_dg_5_1_c_04.stl"/>
    <mesh name="ll_dg_5_1_c_05" content_type="model/stl" file="meshes/ll_dg_5_1_c_05.stl"/>
    <mesh name="ll_dg_5_1_c_06" content_type="model/stl" file="meshes/ll_dg_5_1_c_06.stl"/>
    <mesh name="ll_dg_5_1_c_07" content_type="model/stl" file="meshes/ll_dg_5_1_c_07.stl"/>
    <mesh name="ll_dg_5_2_c_00" content_type="model/stl" file="meshes/ll_dg_5_2_c_00.stl"/>
    <mesh name="ll_dg_5_2_c_01" content_type="model/stl" file="meshes/ll_dg_5_2_c_01.stl"/>
    <mesh name="ll_dg_5_2_c_02" content_type="model/stl" file="meshes/ll_dg_5_2_c_02.stl"/>
    <mesh name="ll_dg_5_2_c_03" content_type="model/stl" file="meshes/ll_dg_5_2_c_03.stl"/>
    <mesh name="ll_dg_5_2_c_04" content_type="model/stl" file="meshes/ll_dg_5_2_c_04.stl"/>
    <mesh name="ll_dg_5_2_c_05" content_type="model/stl" file="meshes/ll_dg_5_2_c_05.stl"/>
    <mesh name="ll_dg_5_2_c_06" content_type="model/stl" file="meshes/ll_dg_5_2_c_06.stl"/>
    <mesh name="ll_dg_5_2_c_07" content_type="model/stl" file="meshes/ll_dg_5_2_c_07.stl"/>
    <mesh name="ll_dg_5_3_c_00" content_type="model/stl" file="meshes/ll_dg_5_3_c_00.stl"/>
    <mesh name="ll_dg_5_3_c_01" content_type="model/stl" file="meshes/ll_dg_5_3_c_01.stl"/>
    <mesh name="ll_dg_5_3_c_02" content_type="model/stl" file="meshes/ll_dg_5_3_c_02.stl"/>
    <mesh name="ll_dg_5_3_c_03" content_type="model/stl" file="meshes/ll_dg_5_3_c_03.stl"/>
    <mesh name="ll_dg_5_3_c_04" content_type="model/stl" file="meshes/ll_dg_5_3_c_04.stl"/>
    <mesh name="ll_dg_5_3_c_05" content_type="model/stl" file="meshes/ll_dg_5_3_c_05.stl"/>
    <mesh name="ll_dg_5_3_c_06" content_type="model/stl" file="meshes/ll_dg_5_3_c_06.stl"/>
    <mesh name="ll_dg_5_3_c_07" content_type="model/stl" file="meshes/ll_dg_5_3_c_07.stl"/>
    <mesh name="ll_dg_5_4_c_00" content_type="model/stl" file="meshes/ll_dg_5_4_c_00.stl"/>
    <mesh name="ll_dg_5_4_c_01" content_type="model/stl" file="meshes/ll_dg_5_4_c_01.stl"/>
    <mesh name="ll_dg_5_4_c_02" content_type="model/stl" file="meshes/ll_dg_5_4_c_02.stl"/>
    <mesh name="ll_dg_5_4_c_03" content_type="model/stl" file="meshes/ll_dg_5_4_c_03.stl"/>
    <mesh name="ll_dg_5_4_c_04" content_type="model/stl" file="meshes/ll_dg_5_4_c_04.stl"/>
    <mesh name="ll_dg_5_4_c_05" content_type="model/stl" file="meshes/ll_dg_5_4_c_05.stl"/>
    <mesh name="ll_dg_5_4_c_06" content_type="model/stl" file="meshes/ll_dg_5_4_c_06.stl"/>
    <mesh name="ll_dg_5_4_c_07" content_type="model/stl" file="meshes/ll_dg_5_4_c_07.stl"/>
    <mesh name="ll_dg_5_tip_c_00" content_type="model/stl" file="meshes/ll_dg_5_tip_c_00.stl"/>
    <mesh name="ll_dg_5_tip_c_01" content_type="model/stl" file="meshes/ll_dg_5_tip_c_01.stl"/>
    <mesh name="ll_dg_5_tip_c_02" content_type="model/stl" file="meshes/ll_dg_5_tip_c_02.stl"/>
    <mesh name="ll_dg_5_tip_c_03" content_type="model/stl" file="meshes/ll_dg_5_tip_c_03.stl"/>
    <mesh name="ll_dg_5_tip_c_04" content_type="model/stl" file="meshes/ll_dg_5_tip_c_04.stl"/>
    <mesh name="ll_dg_5_tip_c_05" content_type="model/stl" file="meshes/ll_dg_5_tip_c_05.stl"/>
    <mesh name="ll_dg_5_tip_c_06" content_type="model/stl" file="meshes/ll_dg_5_tip_c_06.stl"/>
    <mesh name="ll_dg_5_tip_c_07" content_type="model/stl" file="meshes/ll_dg_5_tip_c_07.stl"/>
  </asset>

  <worldbody>
    <geom type="mesh" mesh="ll_dg_mount_c_00"/>
    <geom type="mesh" mesh="ll_dg_mount_c_01"/>
    <geom type="mesh" mesh="ll_dg_mount_c_02"/>
    <geom type="mesh" mesh="ll_dg_mount_c_03"/>
    <geom type="mesh" mesh="ll_dg_mount_c_04"/>
    <geom type="mesh" mesh="ll_dg_mount_c_05"/>
    <geom type="mesh" mesh="ll_dg_mount_c_06"/>
    <geom type="mesh" mesh="ll_dg_mount_c_07"/>
    <geom pos="0 0 0.004" type="mesh" mesh="ll_dg_base_c_00"/>
    <geom pos="0 0 0.004" quat="1 0 0 0" type="mesh" mesh="ll_dg_base_c_01"/>
    <geom pos="0 0 0.004" quat="1 0 0 0" type="mesh" mesh="ll_dg_base_c_02"/>
    <geom pos="0 0 0.004" quat="1 0 0 0" type="mesh" mesh="ll_dg_base_c_03"/>
    <geom pos="0 0 0.004" quat="1 0 0 0" type="mesh" mesh="ll_dg_base_c_04"/>
    <geom pos="0 0 0.004" quat="1 0 0 0" type="mesh" mesh="ll_dg_base_c_05"/>
    <geom pos="0 0 0.004" quat="1 0 0 0" type="mesh" mesh="ll_dg_base_c_06"/>
    <geom pos="0 0 0.004" quat="1 0 0 0" type="mesh" mesh="ll_dg_base_c_07"/>
    <geom pos="0 0 0.0738" type="mesh" mesh="ll_dg_palm_c_00"/>
    <geom pos="0 0 0.0738" quat="1 0 0 0" type="mesh" mesh="ll_dg_palm_c_01"/>
    <geom pos="0 0 0.0738" quat="1 0 0 0" type="mesh" mesh="ll_dg_palm_c_02"/>
    <geom pos="0 0 0.0738" quat="1 0 0 0" type="mesh" mesh="ll_dg_palm_c_03"/>
    <geom pos="0 0 0.0738" quat="1 0 0 0" type="mesh" mesh="ll_dg_palm_c_04"/>
    <geom pos="0 0 0.0738" quat="1 0 0 0" type="mesh" mesh="ll_dg_palm_c_05"/>
    <geom pos="0 0 0.0738" quat="1 0 0 0" type="mesh" mesh="ll_dg_palm_c_06"/>
    <geom pos="0 0 0.0738" quat="1 0 0 0" type="mesh" mesh="ll_dg_palm_c_07"/>
    <body name="ll_dg_1_1" pos="-0.0162 -0.019 0.0866">
      <inertial pos="0.021473 3.1163e-06 0.0028146" quat="0.414969 0.572521 0.572945 0.414433" mass="0.045" diaginertia="1.3718e-05 1.31155e-05 3.31624e-06"/>
      <joint name="lj_dg_1_1" pos="0 0 0" axis="1 0 0" range="-0.890118 0.383972" actuatorfrcrange="-7.5 7.5"/>
      <geom type="mesh" mesh="ll_dg_1_1_c_00"/>
      <geom type="mesh" mesh="ll_dg_1_1_c_01"/>
      <geom type="mesh" mesh="ll_dg_1_1_c_02"/>
      <geom type="mesh" mesh="ll_dg_1_1_c_03"/>
      <geom type="mesh" mesh="ll_dg_1_1_c_04"/>
      <geom type="mesh" mesh="ll_dg_1_1_c_05"/>
      <geom type="mesh" mesh="ll_dg_1_1_c_06"/>
      <geom type="mesh" mesh="ll_dg_1_1_c_07"/>
      <body name="ll_dg_1_2" pos="0.04195 0 0">
        <inertial pos="-0.00055633 -0.0155 0.00055633" quat="0.59634 0.690357 -0.379972 0.152995" mass="0.025" diaginertia="2.07162e-06 1.99661e-06 1.37777e-06"/>
        <joint name="lj_dg_1_2" pos="0 0 0" axis="0 0 1" range="0 3.14159" actuatorfrcrange="-7.5 7.5"/>
        <geom type="mesh" mesh="ll_dg_1_2_c_00"/>
        <geom type="mesh" mesh="ll_dg_1_2_c_01"/>
        <geom type="mesh" mesh="ll_dg_1_2_c_02"/>
        <geom type="mesh" mesh="ll_dg_1_2_c_03"/>
        <geom type="mesh" mesh="ll_dg_1_2_c_04"/>
        <geom type="mesh" mesh="ll_dg_1_2_c_05"/>
        <geom type="mesh" mesh="ll_dg_1_2_c_06"/>
        <geom type="mesh" mesh="ll_dg_1_2_c_07"/>
        <body name="ll_dg_1_3" pos="0 -0.031 0">
          <inertial pos="-2.3008e-05 -0.014842 4.7446e-06" quat="0.525398 0.474739 -0.523748 0.473568" mass="0.045" diaginertia="6.4181e-06 6.01585e-06 2.42154e-06"/>
          <joint name="lj_dg_1_3" pos="0 0 0" axis="1 0 0" range="-1.5708 1.5708" actuatorfrcrange="-7.5 7.5"/>
          <geom type="mesh" mesh="ll_dg_1_3_c_00"/>
          <geom type="mesh" mesh="ll_dg_1_3_c_01"/>
          <geom type="mesh" mesh="ll_dg_1_3_c_02"/>
          <geom type="mesh" mesh="ll_dg_1_3_c_03"/>
          <geom type="mesh" mesh="ll_dg_1_3_c_04"/>
          <geom type="mesh" mesh="ll_dg_1_3_c_05"/>
          <geom type="mesh" mesh="ll_dg_1_3_c_06"/>
          <geom type="mesh" mesh="ll_dg_1_3_c_07"/>
          <body name="ll_dg_1_4" pos="0 -0.0388 0">
            <inertial pos="0.000182282 -0.0140657 0.000732812" quat="0.475371 0.555092 -0.521074 0.440882" mass="0.05" diaginertia="2.0651e-05 2.02971e-05 3.29812e-06"/>
            <joint name="lj_dg_1_4" pos="0 0 0" axis="1 0 0" range="-1.5708 1.5708" actuatorfrcrange="-7.5 7.5"/>
            <geom type="mesh" mesh="ll_dg_1_4_c_00"/>
            <geom type="mesh" mesh="ll_dg_1_4_c_01"/>
            <geom type="mesh" mesh="ll_dg_1_4_c_02"/>
            <geom type="mesh" mesh="ll_dg_1_4_c_03"/>
            <geom type="mesh" mesh="ll_dg_1_4_c_04"/>
            <geom type="mesh" mesh="ll_dg_1_4_c_05"/>
            <geom type="mesh" mesh="ll_dg_1_4_c_06"/>
            <geom type="mesh" mesh="ll_dg_1_4_c_07"/>
            <geom pos="0 -0.0363 0" quat="1 0 0 0" type="mesh" mesh="ll_dg_1_tip_c_00"/>
            <geom pos="0 -0.0363 0" quat="1 0 0 0" type="mesh" mesh="ll_dg_1_tip_c_01"/>
            <geom pos="0 -0.0363 0" quat="1 0 0 0" type="mesh" mesh="ll_dg_1_tip_c_02"/>
            <geom pos="0 -0.0363 0" quat="1 0 0 0" type="mesh" mesh="ll_dg_1_tip_c_03"/>
            <geom pos="0 -0.0363 0" quat="1 0 0 0" type="mesh" mesh="ll_dg_1_tip_c_04"/>
            <geom pos="0 -0.0363 0" quat="1 0 0 0" type="mesh" mesh="ll_dg_1_tip_c_05"/>
            <geom pos="0 -0.0363 0" quat="1 0 0 0" type="mesh" mesh="ll_dg_1_tip_c_06"/>
            <geom pos="0 -0.0363 0" quat="1 0 0 0" type="mesh" mesh="ll_dg_1_tip_c_07"/>
          </body>
        </body>
      </body>
    </body>
    <body name="ll_dg_2_1" pos="-0.0071 -0.027 0.1399">
      <inertial pos="0.0010606 -0.00058566 0.023499" quat="0.666108 0.307837 0.308411 0.605327" mass="0.045" diaginertia="9.54523e-06 7.99297e-06 5.6344e-06"/>
      <joint name="lj_dg_2_1" pos="0 0 0" axis="1 0 0" range="-0.610865 0.418879" actuatorfrcrange="-7.5 7.5"/>
      <geom type="mesh" mesh="ll_dg_2_1_c_00"/>
      <geom type="mesh" mesh="ll_dg_2_1_c_01"/>
      <geom type="mesh" mesh="ll_dg_2_1_c_02"/>
      <geom type="mesh" mesh="ll_dg_2_1_c_03"/>
      <geom type="mesh" mesh="ll_dg_2_1_c_04"/>
      <geom type="mesh" mesh="ll_dg_2_1_c_05"/>
      <geom type="mesh" mesh="ll_dg_2_1_c_06"/>
      <geom type="mesh" mesh="ll_dg_2_1_c_07"/>
      <body name="ll_dg_2_2" pos="0.01765 0 0.0265">
        <inertial pos="-4.7446e-06 2.3008e-05 0.023958" quat="0.998727 0.0504191 0.000239574 0.00141058" mass="0.045" diaginertia="6.4181e-06 6.01585e-06 2.42154e-06"/>
        <joint name="lj_dg_2_2" pos="0 0 0" axis="0 1 0" range="0 2.00713" actuatorfrcrange="-7.5 7.5"/>
        <geom type="mesh" mesh="ll_dg_2_2_c_00"/>
        <geom type="mesh" mesh="ll_dg_2_2_c_01"/>
        <geom type="mesh" mesh="ll_dg_2_2_c_02"/>
        <geom type="mesh" mesh="ll_dg_2_2_c_03"/>
        <geom type="mesh" mesh="ll_dg_2_2_c_04"/>
        <geom type="mesh" mesh="ll_dg_2_2_c_05"/>
        <geom type="mesh" mesh="ll_dg_2_2_c_06"/>
        <geom type="mesh" mesh="ll_dg_2_2_c_07"/>
        <body name="ll_dg_2_3" pos="0 0 0.0388">
          <inertial pos="-4.7446e-06 2.3008e-05 0.023958" quat="0.998727 0.0504191 0.000239574 0.00141058" mass="0.045" diaginertia="6.4181e-06 6.01585e-06 2.42154e-06"/>
          <joint name="lj_dg_2_3" pos="0 0 0" axis="0 1 0" range="-1.5708 1.5708" actuatorfrcrange="-7.5 7.5"/>
          <geom type="mesh" mesh="ll_dg_2_3_c_00"/>
          <geom type="mesh" mesh="ll_dg_2_3_c_01"/>
          <geom type="mesh" mesh="ll_dg_2_3_c_02"/>
          <geom type="mesh" mesh="ll_dg_2_3_c_03"/>
          <geom type="mesh" mesh="ll_dg_2_3_c_04"/>
          <geom type="mesh" mesh="ll_dg_2_3_c_05"/>
          <geom type="mesh" mesh="ll_dg_2_3_c_06"/>
          <geom type="mesh" mesh="ll_dg_2_3_c_07"/>
          <body name="ll_dg_2_4" pos="0 0 0.0388">
            <inertial pos="4.45695e-05 -0.00389127 0.0160588" quat="0.526445 0.843914 -0.0138863 0.10233" mass="0.03" diaginertia="6.58495e-06 5.22897e-06 2.6024e-06"/>
            <joint name="lj_dg_2_4" pos="0 0 0" axis="0 1 0" range="-1.5708 1.5708" actuatorfrcrange="-7.5 7.5"/>
            <geom type="mesh" mesh="ll_dg_2_4_c_00"/>
            <geom type="mesh" mesh="ll_dg_2_4_c_01"/>
            <geom type="mesh" mesh="ll_dg_2_4_c_02"/>
            <geom type="mesh" mesh="ll_dg_2_4_c_03"/>
            <geom type="mesh" mesh="ll_dg_2_4_c_04"/>
            <geom type="mesh" mesh="ll_dg_2_4_c_05"/>
            <geom type="mesh" mesh="ll_dg_2_4_c_06"/>
            <geom type="mesh" mesh="ll_dg_2_4_c_07"/>
            <geom pos="0 0 0.0255" quat="1 0 0 0" type="mesh" mesh="ll_dg_2_tip_c_00"/>
            <geom pos="0 0 0.0255" quat="1 0 0 0" type="mesh" mesh="ll_dg_2_tip_c_01"/>
            <geom pos="0 0 0.0255" quat="1 0 0 0" type="mesh" mesh="ll_dg_2_tip_c_02"/>
            <geom pos="0 0 0.0255" quat="1 0 0 0" type="mesh" mesh="ll_dg_2_tip_c_03"/>
            <geom pos="0 0 0.0255" quat="1 0 0 0" type="mesh" mesh="ll_dg_2_tip_c_04"/>
            <geom pos="0 0 0.0255" quat="1 0 0 0" type="mesh" mesh="ll_dg_2_tip_c_05"/>
            <geom pos="0 0 0.0255" type="mesh" mesh="ll_dg_2_tip_c_06"/>
            <geom pos="0 0 0.0255" quat="1 0 0 0" type="mesh" mesh="ll_dg_2_tip_c_07"/>
          </body>
        </body>
      </body>
    </body>
    <body name="ll_dg_3_1" pos="-0.0071 -0.0025 0.1439">
      <inertial pos="0.0012558 -0.00017703 0.023374" quat="0.648691 0.313074 0.303523 0.623746" mass="0.045" diaginertia="9.33725e-06 7.69718e-06 5.31337e-06"/>
      <joint name="lj_dg_3_1" pos="0 0 0" axis="1 0 0" range="-0.610865 0.610865" actuatorfrcrange="-7.5 7.5"/>
      <geom type="mesh" mesh="ll_dg_3_1_c_00"/>
      <geom type="mesh" mesh="ll_dg_3_1_c_01"/>
      <geom type="mesh" mesh="ll_dg_3_1_c_02"/>
      <geom type="mesh" mesh="ll_dg_3_1_c_03"/>
      <geom type="mesh" mesh="ll_dg_3_1_c_04"/>
      <geom type="mesh" mesh="ll_dg_3_1_c_05"/>
      <geom type="mesh" mesh="ll_dg_3_1_c_06"/>
      <geom type="mesh" mesh="ll_dg_3_1_c_07"/>
      <body name="ll_dg_3_2" pos="0.01765 0 0.0265">
        <inertial pos="-4.7446e-06 2.3008e-05 0.023958" quat="0.998727 0.0504191 0.000239574 0.00141058" mass="0.045" diaginertia="6.4181e-06 6.01585e-06 2.42154e-06"/>
        <joint name="lj_dg_3_2" pos="0 0 0" axis="0 1 0" range="0 1.95477" actuatorfrcrange="-7.5 7.5"/>
        <geom type="mesh" mesh="ll_dg_3_2_c_00"/>
        <geom type="mesh" mesh="ll_dg_3_2_c_01"/>
        <geom type="mesh" mesh="ll_dg_3_2_c_02"/>
        <geom type="mesh" mesh="ll_dg_3_2_c_03"/>
        <geom type="mesh" mesh="ll_dg_3_2_c_04"/>
        <geom type="mesh" mesh="ll_dg_3_2_c_05"/>
        <geom type="mesh" mesh="ll_dg_3_2_c_06"/>
        <geom type="mesh" mesh="ll_dg_3_2_c_07"/>
        <body name="ll_dg_3_3" pos="0 0 0.0388">
          <inertial pos="-4.7446e-06 2.3008e-05 0.023958" quat="0.998727 0.0504191 0.000239574 0.00141058" mass="0.045" diaginertia="6.4181e-06 6.01585e-06 2.42154e-06"/>
          <joint name="lj_dg_3_3" pos="0 0 0" axis="0 1 0" range="-1.5708 1.5708" actuatorfrcrange="-7.5 7.5"/>
          <geom type="mesh" mesh="ll_dg_3_3_c_00"/>
          <geom type="mesh" mesh="ll_dg_3_3_c_01"/>
          <geom type="mesh" mesh="ll_dg_3_3_c_02"/>
          <geom type="mesh" mesh="ll_dg_3_3_c_03"/>
          <geom type="mesh" mesh="ll_dg_3_3_c_04"/>
          <geom type="mesh" mesh="ll_dg_3_3_c_05"/>
          <geom type="mesh" mesh="ll_dg_3_3_c_06"/>
          <geom type="mesh" mesh="ll_dg_3_3_c_07"/>
          <body name="ll_dg_3_4" pos="0 0 0.0388">
            <inertial pos="4.45695e-05 -0.00389127 0.0160588" quat="0.526445 0.843914 -0.0138863 0.10233" mass="0.03" diaginertia="6.58495e-06 5.22897e-06 2.6024e-06"/>
            <joint name="lj_dg_3_4" pos="0 0 0" axis="0 1 0" range="-1.5708 1.5708" actuatorfrcrange="-7.5 7.5"/>
            <geom type="mesh" mesh="ll_dg_3_4_c_00"/>
            <geom type="mesh" mesh="ll_dg_3_4_c_01"/>
            <geom type="mesh" mesh="ll_dg_3_4_c_02"/>
            <geom type="mesh" mesh="ll_dg_3_4_c_03"/>
            <geom type="mesh" mesh="ll_dg_3_4_c_04"/>
            <geom type="mesh" mesh="ll_dg_3_4_c_05"/>
            <geom type="mesh" mesh="ll_dg_3_4_c_06"/>
            <geom type="mesh" mesh="ll_dg_3_4_c_07"/>
            <geom pos="0 0 0.0255" quat="1 0 0 0" type="mesh" mesh="ll_dg_3_tip_c_00"/>
            <geom pos="0 0 0.0255" quat="1 0 0 0" type="mesh" mesh="ll_dg_3_tip_c_01"/>
            <geom pos="0 0 0.0255" quat="1 0 0 0" type="mesh" mesh="ll_dg_3_tip_c_02"/>
            <geom pos="0 0 0.0255" quat="1 0 0 0" type="mesh" mesh="ll_dg_3_tip_c_03"/>
            <geom pos="0 0 0.0255" quat="1 0 0 0" type="mesh" mesh="ll_dg_3_tip_c_04"/>
            <geom pos="0 0 0.0255" quat="1 0 0 0" type="mesh" mesh="ll_dg_3_tip_c_05"/>
            <geom pos="0 0 0.0255" type="mesh" mesh="ll_dg_3_tip_c_06"/>
            <geom pos="0 0 0.0255" quat="1 0 0 0" type="mesh" mesh="ll_dg_3_tip_c_07"/>
          </body>
        </body>
      </body>
    </body>
    <body name="ll_dg_4_1" pos="-0.0071 0.022 0.1359">
      <inertial pos="0.001061 0.00024417 0.023499" quat="0.632598 0.317074 0.297256 0.641032" mass="0.045" diaginertia="9.53287e-06 8.0012e-06 5.63792e-06"/>
      <joint name="lj_dg_4_1" pos="0 0 0" axis="1 0 0" range="-0.418879 0.610865" actuatorfrcrange="-7.5 7.5"/>
      <geom type="mesh" mesh="ll_dg_4_1_c_00"/>
      <geom type="mesh" mesh="ll_dg_4_1_c_01"/>
      <geom type="mesh" mesh="ll_dg_4_1_c_02"/>
      <geom type="mesh" mesh="ll_dg_4_1_c_03"/>
      <geom type="mesh" mesh="ll_dg_4_1_c_04"/>
      <geom type="mesh" mesh="ll_dg_4_1_c_05"/>
      <geom type="mesh" mesh="ll_dg_4_1_c_06"/>
      <geom type="mesh" mesh="ll_dg_4_1_c_07"/>
      <body name="ll_dg_4_2" pos="0.01765 0 0.0265">
        <inertial pos="-4.7446e-06 2.3008e-05 0.023958" quat="0.998727 0.0504191 0.000239574 0.00141058" mass="0.045" diaginertia="6.4181e-06 6.01585e-06 2.42154e-06"/>
        <joint name="lj_dg_4_2" pos="0 0 0" axis="0 1 0" range="0 1.90241" actuatorfrcrange="-7.5 7.5"/>
        <geom type="mesh" mesh="ll_dg_4_2_c_00"/>
        <geom type="mesh" mesh="ll_dg_4_2_c_01"/>
        <geom type="mesh" mesh="ll_dg_4_2_c_02"/>
        <geom type="mesh" mesh="ll_dg_4_2_c_03"/>
        <geom type="mesh" mesh="ll_dg_4_2_c_04"/>
        <geom type="mesh" mesh="ll_dg_4_2_c_05"/>
        <geom type="mesh" mesh="ll_dg_4_2_c_06"/>
        <geom type="mesh" mesh="ll_dg_4_2_c_07"/>
        <body name="ll_dg_4_3" pos="0 0 0.0388">
          <inertial pos="-4.7446e-06 2.3008e-05 0.023958" quat="0.998727 0.0504191 0.000239574 0.00141058" mass="0.045" diaginertia="6.4181e-06 6.01585e-06 2.42154e-06"/>
          <joint name="lj_dg_4_3" pos="0 0 0" axis="0 1 0" range="-1.5708 1.5708" actuatorfrcrange="-7.5 7.5"/>
          <geom type="mesh" mesh="ll_dg_4_3_c_00"/>
          <geom type="mesh" mesh="ll_dg_4_3_c_01"/>
          <geom type="mesh" mesh="ll_dg_4_3_c_02"/>
          <geom type="mesh" mesh="ll_dg_4_3_c_03"/>
          <geom type="mesh" mesh="ll_dg_4_3_c_04"/>
          <geom type="mesh" mesh="ll_dg_4_3_c_05"/>
          <geom type="mesh" mesh="ll_dg_4_3_c_06"/>
          <geom type="mesh" mesh="ll_dg_4_3_c_07"/>
          <body name="ll_dg_4_4" pos="0 0 0.0388">
            <inertial pos="4.45695e-05 -0.00389127 0.0160588" quat="0.526445 0.843914 -0.0138863 0.10233" mass="0.03" diaginertia="6.58495e-06 5.22897e-06 2.6024e-06"/>
            <joint name="lj_dg_4_4" pos="0 0 0" axis="0 1 0" range="-1.5708 1.5708" actuatorfrcrange="-7.5 7.5"/>
            <geom type="mesh" mesh="ll_dg_4_4_c_00"/>
            <geom type="mesh" mesh="ll_dg_4_4_c_01"/>
            <geom type="mesh" mesh="ll_dg_4_4_c_02"/>
            <geom type="mesh" mesh="ll_dg_4_4_c_03"/>
            <geom type="mesh" mesh="ll_dg_4_4_c_04"/>
            <geom type="mesh" mesh="ll_dg_4_4_c_05"/>
            <geom type="mesh" mesh="ll_dg_4_4_c_06"/>
            <geom type="mesh" mesh="ll_dg_4_4_c_07"/>
            <geom pos="0 0 0.0255" quat="1 0 0 0" type="mesh" mesh="ll_dg_4_tip_c_00"/>
            <geom pos="0 0 0.0255" quat="1 0 0 0" type="mesh" mesh="ll_dg_4_tip_c_01"/>
            <geom pos="0 0 0.0255" quat="1 0 0 0" type="mesh" mesh="ll_dg_4_tip_c_02"/>
            <geom pos="0 0 0.0255" quat="1 0 0 0" type="mesh" mesh="ll_dg_4_tip_c_03"/>
            <geom pos="0 0 0.0255" quat="1 0 0 0" type="mesh" mesh="ll_dg_4_tip_c_04"/>
            <geom pos="0 0 0.0255" quat="1 0 0 0" type="mesh" mesh="ll_dg_4_tip_c_05"/>
            <geom pos="0 0 0.0255" type="mesh" mesh="ll_dg_4_tip_c_06"/>
            <geom pos="0 0 0.0255" quat="1 0 0 0" type="mesh" mesh="ll_dg_4_tip_c_07"/>
          </body>
        </body>
      </body>
    </body>
    <body name="ll_dg_5_1" pos="0.0103 0.0195 0.092">
      <inertial pos="-0.0045287 0.025016 0.014025" quat="0.476613 -0.146609 0.0894555 0.862174" mass="0.055" diaginertia="2.5688e-05 2.34482e-05 9.43772e-06"/>
      <joint name="lj_dg_5_1" pos="0 0 0" axis="0 0 1" range="-1.0472 0.0174533" actuatorfrcrange="-7.5 7.5"/>
      <geom type="mesh" mesh="ll_dg_5_1_c_00"/>
      <geom type="mesh" mesh="ll_dg_5_1_c_01"/>
      <geom type="mesh" mesh="ll_dg_5_1_c_02"/>
      <geom type="mesh" mesh="ll_dg_5_1_c_03"/>
      <geom type="mesh" mesh="ll_dg_5_1_c_04"/>
      <geom type="mesh" mesh="ll_dg_5_1_c_05"/>
      <geom type="mesh" mesh="ll_dg_5_1_c_06"/>
      <geom type="mesh" mesh="ll_dg_5_1_c_07"/>
      <body name="ll_dg_5_2" pos="0 0.028 0.0381">
        <inertial pos="0.00055633 0.00055633 0.0155" quat="0.376865 -0.160497 0.0664802 0.909832" mass="0.025" diaginertia="2.07162e-06 1.99661e-06 1.37777e-06"/>
        <joint name="lj_dg_5_2" pos="0 0 0" axis="1 0 0" range="-0.610865 0.418879" actuatorfrcrange="-7.5 7.5"/>
        <geom type="mesh" mesh="ll_dg_5_2_c_00"/>
        <geom type="mesh" mesh="ll_dg_5_2_c_01"/>
        <geom type="mesh" mesh="ll_dg_5_2_c_02"/>
        <geom type="mesh" mesh="ll_dg_5_2_c_03"/>
        <geom type="mesh" mesh="ll_dg_5_2_c_04"/>
        <geom type="mesh" mesh="ll_dg_5_2_c_05"/>
        <geom type="mesh" mesh="ll_dg_5_2_c_06"/>
        <geom type="mesh" mesh="ll_dg_5_2_c_07"/>
        <body name="ll_dg_5_3" pos="0 0 0.031">
          <inertial pos="4.7446e-06 2.3008e-05 0.014842" quat="0.998727 -0.0504191 0.000239574 -0.00141058" mass="0.045" diaginertia="6.4181e-06 6.01585e-06 2.42154e-06"/>
          <joint name="lj_dg_5_3" pos="0 0 0" axis="0 1 0" range="-1.5708 1.5708" actuatorfrcrange="-7.5 7.5"/>
          <geom type="mesh" mesh="ll_dg_5_3_c_00"/>
          <geom type="mesh" mesh="ll_dg_5_3_c_01"/>
          <geom type="mesh" mesh="ll_dg_5_3_c_02"/>
          <geom type="mesh" mesh="ll_dg_5_3_c_03"/>
          <geom type="mesh" mesh="ll_dg_5_3_c_04"/>
          <geom type="mesh" mesh="ll_dg_5_3_c_05"/>
          <geom type="mesh" mesh="ll_dg_5_3_c_06"/>
          <geom type="mesh" mesh="ll_dg_5_3_c_07"/>
          <body name="ll_dg_5_4" pos="0 0 0.0388">
            <inertial pos="5.20519e-05 -0.00381428 0.0176292" quat="0.94731 -0.315965 -0.0407461 0.0333232" mass="0.05" diaginertia="1.67135e-05 1.18895e-05 7.5328e-06"/>
            <joint name="lj_dg_5_4" pos="0 0 0" axis="0 1 0" range="-1.5708 1.5708" actuatorfrcrange="-7.5 7.5"/>
            <geom type="mesh" mesh="ll_dg_5_4_c_00"/>
            <geom type="mesh" mesh="ll_dg_5_4_c_01"/>
            <geom type="mesh" mesh="ll_dg_5_4_c_02"/>
            <geom type="mesh" mesh="ll_dg_5_4_c_03"/>
            <geom type="mesh" mesh="ll_dg_5_4_c_04"/>
            <geom type="mesh" mesh="ll_dg_5_4_c_05"/>
            <geom type="mesh" mesh="ll_dg_5_4_c_06"/>
            <geom type="mesh" mesh="ll_dg_5_4_c_07"/>
            <geom pos="0 0 0.0363" quat="1 0 0 0" type="mesh" mesh="ll_dg_5_tip_c_00"/>
            <geom pos="0 0 0.0363" quat="1 0 0 0" type="mesh" mesh="ll_dg_5_tip_c_01"/>
            <geom pos="0 0 0.0363" quat="1 0 0 0" type="mesh" mesh="ll_dg_5_tip_c_02"/>
            <geom pos="0 0 0.0363" quat="1 0 0 0" type="mesh" mesh="ll_dg_5_tip_c_03"/>
            <geom pos="0 0 0.0363" quat="1 0 0 0" type="mesh" mesh="ll_dg_5_tip_c_04"/>
            <geom pos="0 0 0.0363" quat="1 0 0 0" type="mesh" mesh="ll_dg_5_tip_c_05"/>
            <geom pos="0 0 0.0363" type="mesh" mesh="ll_dg_5_tip_c_06"/>
            <geom pos="0 0 0.0363" quat="1 0 0 0" type="mesh" mesh="ll_dg_5_tip_c_07"/>
          </body>
        </body>
      </body>
    </body>
  </worldbody>
</mujoco>
